<?xml version="1.0" encoding="utf-8"?>
<!-- =================================================================================== -->
<!-- |    This document was autogenerated by xacro from reach_5mini_nacho.urdf.xacro   | -->
<!-- |    EDITING THIS FILE BY HAND IS NOT RECOMMENDED                                 | -->
<!-- =================================================================================== -->
<robot name='reach5'>
  <link name="/base">
    <visual>
      <origin rpy="0 0 0" xyz="0.0 0.0 0.0"/>
      <geometry>
        <mesh filename="package://reach_system_one_support/meshes/reach5mini/visual/Base.stl"/>
      </geometry>
    </visual>
    <collision>
      <origin rpy="0.0 1.57079632679 0" xyz="-0.075 0.02 0.0"/>
      <geometry>
        <cylinder length="0.11" radius="0.021"/>
      </geometry>
    </collision>
  </link>
  <link name="/link1">
    <visual>
      <origin rpy="3.14159265359 0.0 0.0" xyz="0.0 0.0 0.02204"/>
      <geometry>
        <mesh filename="package://reach_system_one_support/meshes/reach5mini/visual/Base.stl"/>
      </geometry>
    </visual>
    <collision>
      <origin rpy="0 0 0" xyz="0 0 0.01"/>
      <geometry>
        <!--<box size="0.001 0.001 0.001" /> -->
        <cylinder length="0.055" radius="0.021"/>
      </geometry>
    </collision>
  </link>
  <link name="/link2">
    <visual>
      <origin rpy="0.0 0 0" xyz="0.0 0.0 0.001"/>
      <geometry>
        <mesh filename="package://reach_system_one_support/meshes/reach5mini/visual/Base.stl"/>
      </geometry>
    </visual>
    <collision>
      <origin rpy="0.25 -1.57079632679 0" xyz="0.075 0 -0.0025"/>
      <geometry>
        <!-- <box size="0.001 0.001 0.001" /> -->
        <cylinder length="0.12" radius="0.02"/>
      </geometry>
    </collision>
  </link>
  <link name="/link3">
    <visual>
      <origin rpy="-1.57079632679 0.0 3.14159265359" xyz="0.02 -0.02416 0.0"/>
      <geometry>
        <mesh filename="package://reach_system_one_support/meshes/reach5mini/visual/Base.stl"/>
      </geometry>
    </visual>
    <collision>
      <origin rpy="1.57079632679 0 0" xyz="0.02 -0.01 0.0"/>
      <geometry>
        <!--<box size="0.001 0.001 0.001" />-->
        <cylinder length="0.04" radius="0.021"/>
      </geometry>
    </collision>
  </link>
  <link name="/link4">
    <visual>
      <origin rpy="0 0 0" xyz="0.0 0.0 0.02137 "/>
      <geometry>
        <mesh filename="package://reach_system_one_support/meshes/reach5mini/visual/Base.stl"/>
      </geometry>
    </visual>
    <collision>
      <origin rpy="0 0 0" xyz="0 0 0.085"/>
      <geometry>
        <!--<box size="0.001 0.001 0.001" /> -->
        <cylinder length="0.110" radius="0.0215"/>
      </geometry>
    </collision>
  </link>
  <link name="/jaw"/>
  <link name="/gripper1">
    <visual>
      <origin rpy="0 0.0 0" xyz="0.0 0.0 0.0"/>
      <geometry>
        <mesh filename="package://reach_system_one_support/meshes/reach5mini/visual/Base.stl"/>
      </geometry>
    </visual>
    <collision>
      <origin rpy="0.0 1.57079632679 0.0" xyz="0.045 -0.01 0.0"/>
      <geometry>
        <box size="0.008 0.028 0.09"/>
      </geometry>
    </collision>
  </link>
  <link name="/gripper2">
    <visual>
      <origin rpy="0 0.0 0" xyz="0.0 0.0 0.0"/>
      <geometry>
        <mesh filename="package://reach_system_one_support/meshes/reach5mini/visual/Base.stl"/>
      </geometry>
    </visual>
    <collision>
      <origin rpy="0.0 1.57079632679 0" xyz="0.045 -0.01 0.0 "/>
      <geometry>
        <box size="0.008 0.028 0.09"/>
      </geometry>
    </collision>
  </link>
  <!--  JOINTS  -->
  <joint name="/joint1" type="revolute">
    <parent link="/base"/>
    <child link="/link1"/>
    <axis xyz="0 0 1"/>
    <origin rpy="3.14159265359 0.0 0.0" xyz="0.0 0.0 0.0"/>
    <!--limit effort="30" lower="-0.21" upper="1.47" velocity="0.0547"/        0.072 -->
    <limit effort="30" lower="-3.14159265359" upper="3.14159265359" velocity="0.5"/>
  </joint>
  <joint name="/joint2" type="revolute">
    <parent link="/link1"/>
    <child link="/link2"/>
    <axis xyz="0 0 1"/>
    <origin rpy="-1.57079632679 0.0 0.0" xyz="0.02 0.0 0.0462"/>
    <!--limit effort="30" lower="-0.58" upper="1.606" velocity="0.08327"          0.052/-->
    <limit effort="30" lower="-2.15" upper="1.25" velocity="0.5"/>
    <!-- -1.31, 2.186-->
  </joint>
  <joint name="/joint3" type="revolute">
    <parent link="/link2"/>
    <child link="/link3"/>
    <axis xyz="0 0 1"/>
    <origin rpy="0.0 0 0" xyz="0.15071 0.0 0.0"/>
    <!--limit effort="30" lower="-1.46" upper="0.78" velocity="0.0605"    0.085/   0.15331014317-->
    <limit effort="30" lower="-1.29" upper="2.15" velocity="0.5"/>
  </joint>
  <joint name="/joint4" type="revolute">
    <parent link="/link3"/>
    <child link="/link4"/>
    <axis xyz="0 0 1"/>
    <origin rpy="1.57079632679 0 0" xyz="0.020 0.0 0.0"/>
    <limit effort="30" lower="-0.52" upper="5.2" velocity="0.85"/>
  </joint>
  <joint name="/jointJaw" type="fixed">
    <parent link="/link4"/>
    <child link="/jaw"/>
    <axis xyz="0 0 1"/>
    <origin rpy="0 0 0" xyz="0.0 0.0 0.13776"/>
    <!--0.328-->
  </joint>
  <joint name="/gripperjoint1" type="revolute">
    <parent link="/jaw"/>
    <child link="/gripper1"/>
    <axis xyz="0 0 1"/>
    <origin rpy="0 -1.57079632679 0" xyz="0.0 0.0155 0.0"/>
    <!--0.328-->
    <limit effort="30" lower="0" upper="3.14159265359" velocity="0.5"/>
  </joint>
  <joint name="/gripperjoint2" type="revolute">
    <parent link="/jaw"/>
    <child link="/gripper2"/>
    <axis xyz="0 0 1"/>
    <origin rpy="3.14159265359 -1.57079632679 0" xyz="0.0 -0.0155 0.0"/>
    <!--0.328-->
    <limit effort="30" lower="0" upper="0.785398163397" velocity="0.5"/>
    <mimic joint="/gripperjoint1" multiplier="1" offset="0"/>
  </joint>
  <!--
    <transmission name="tran15">
        <type>transmission_interface/SimpleTransmission</type>
        <joint name="R5M_GripperJoint">
            <hardwareInterface>VelocityJointInterface</hardwareInterface>
        </joint>
        <actuator name="motor15">
            <hardwareInterface>VelocityJointInterface</hardwareInterface>
            <mechanicalReduction>1</mechanicalReduction>
        </actuator>
    </transmission>
    <transmission name="tran16">
        <type>transmission_interface/SimpleTransmission</type>
        <joint name="R5M_GripperJoint2">
            <hardwareInterface>VelocityJointInterface</hardwareInterface>
        </joint>
        <actuator name="motor16">
            <hardwareInterface>VelocityJointInterface</hardwareInterface>
            <mechanicalReduction>1</mechanicalReduction>
        </actuator>
    </transmission>
-->
</robot>

