<?xml version="1.0" encoding="utf-8"?>
<!-- =================================================================================== -->
<!-- |    This document was autogenerated by xacro from reach_5mini_no_col.urdf.xacro  | -->
<!-- |    EDITING THIS FILE BY HAND IS NOT RECOMMENDED                                 | -->
<!-- =================================================================================== -->
<robot name="r5m">
  <!-- ############## R5M ############### -->
  <link name="R5M_BaseLink">
    <visual>
      <origin rpy="  0 0 0" xyz="0.130 0.0 00"/>
      <geometry>
        <mesh filename="package://reach_system_one_support/meshes/reach5mini/visual/Base.stl"/>
      </geometry>
      <material name="Grey">
        <color rgba="0.5 0.5 0.5 1.0"/>
      </material>
    </visual>
    <collision>
      <origin rpy="0.0 1.57079632679 0" xyz="0.06 -0.02 0.0"/>
      <geometry>
        <box size="0.001 0.001 0.001"/>
      </geometry>
    </collision>
  </link>
  <joint name="R5M_Joint1" type="revolute">
    <parent link="R5M_BaseLink"/>
    <child link="R5M_Shoulder"/>
    <axis xyz="0 0 1"/>
    <origin rpy="0.0 0.0 0.0" xyz="0.130 0.0 0.0"/>
    <!--limit effort="30" lower="-0.21" upper="1.47" velocity="0.0547"/        0.072 -->
    <limit effort="30" lower="-3.14159265359" upper="3.14159265359" velocity="0.5"/>
  </joint>
  <link name="R5M_Shoulder">
    <visual>
      <origin rpy="3.14159265359 1.57079632679 0" xyz="0.0 0 0.018"/>
      <geometry>
        <mesh filename="package://reach_system_one_support/meshes/reach5mini/visual/Base.stl"/>
      </geometry>
      <material name="LightGrey">
        <color rgba="0.75 0.75 0.75 1.0"/>
      </material>
    </visual>
    <collision>
      <origin rpy="0 0 0" xyz="0 0 0.01"/>
      <geometry>
        <box size="0.001 0.001 0.001"/>
      </geometry>
    </collision>
  </link>
  <joint name="R5M_Joint2" type="revolute">
    <parent link="R5M_Shoulder"/>
    size=&quot;0.19 0.04 0.04
        
    <child link="R5M_Biceps"/>
    <axis xyz="0 0 1"/>
    <origin rpy="-1.57079632679 0.0 0.0" xyz="0.020 0.0 0.0462"/>
    <!--limit effort="30" lower="-0.58" upper="1.606" velocity="0.08327"          0.052/-->
    <limit effort="30" lower="-2" upper="1.36" velocity="0.5"/>
  </joint>
  <link name="R5M_Biceps">
    <visual>
      <origin rpy="0 0 0" xyz="0.0 0.0 0.0"/>
      <geometry>
        <mesh filename="package://reach_system_one_support/meshes/reach5mini/visual/Base.stl"/>
      </geometry>
      <material name="Grey">
        <color rgba="0.5 0.5 0.5 1.0"/>
      </material>
    </visual>
    <collision>
      <origin rpy="0.25 -1.57079632679 0" xyz="0.075 0 -0.0025"/>
      <geometry>
        <box size="0.001 0.001 0.001"/>
      </geometry>
    </collision>
  </link>
  <joint name="R5M_Joint3" type="revolute">
    <parent link="R5M_Biceps"/>
    <child link="R5M_Forearm"/>
    <axis xyz="0 0 1"/>
    <origin rpy="0.0 0 0" xyz="0.15071 0.0 0.0"/>
    <!--limit effort="30" lower="-1.46" upper="0.78" velocity="0.0605"    0.085/   0.15331014317-->
    <limit effort="30" lower="-1.25" upper="1.8" velocity="0.5"/>
  </joint>
  <link name="R5M_Forearm">
    <visual>
      <origin rpy="-1.57079632679 0 -1.57079632679" xyz="0.02 -0.025 0"/>
      <geometry>
        <mesh filename="package://reach_system_one_support/meshes/reach5mini/visual/Base.stl"/>
      </geometry>
      <material name="LightGrey">
        <color rgba="0.75 0.75 0.75 1.0"/>
      </material>
    </visual>
    <collision>
      <origin rpy="1.57079632679 0 0" xyz="0.02 -0.01 0.0"/>
      <geometry>
        <box size="0.001 0.001 0.001"/>
      </geometry>
    </collision>
  </link>
  <joint name="R5M_Joint4" type="continuous">
    <parent link="R5M_Forearm"/>
    <child link="R5M_Palm"/>
    <axis xyz="0 0 1"/>
    <origin rpy="1.57079632679 0 0" xyz="0.020 0.0 0.0"/>
    <!--limit effort="30" lower="-3.14" upper="3.12" velocity="1.5305"/-->
    <limit effort="30" velocity="1"/>
  </joint>
  <link name="R5M_Palm">
    <visual>
      <origin rpy="0 0 0" xyz="0.0 0.0 0.029 "/>
      <geometry>
        <mesh filename="package://reach_system_one_support/meshes/reach5mini/visual/Base.stl"/>
      </geometry>
      <material name="LightBlack">
        <color rgba="0.2 0.2 0.2 1.0"/>
      </material>
    </visual>
    <collision>
      <origin rpy="0 0 0" xyz="0 0 0.085"/>
      <geometry>
        <box size="0.001 0.001 0.001"/>
      </geometry>
    </collision>
  </link>
  <joint name="R5M_Palm_to_Jaw" type="fixed">
    <parent link="R5M_Palm"/>
    <child link="R5M_Jaw"/>
    <axis xyz="0 0 1"/>
    <origin rpy="0 0 0" xyz="0.0 0.0 0.155"/>
    <!--0.328-->
  </joint>
  <link name="R5M_Jaw"/>
  <joint name="R5M_GripperJoint" type="revolute">
    <parent link="R5M_Jaw"/>
    <child link="R5M_Gripper_Left"/>
    <axis xyz="1 0 0"/>
    <origin rpy="0 0 0" xyz="0.0 -0.0155 -0.0125"/>
    <!--0.328-->
    <limit effort="30" lower="-0.63" upper="0" velocity="0.5"/>
  </joint>
  <joint name="R5M_GripperJoint2" type="revolute">
    <parent link="R5M_Jaw"/>
    <child link="R5M_Gripper_Right"/>
    <axis xyz="1 0 0"/>
    <origin rpy="0 0 -3.14159265359" xyz="0.0 0.0155 -0.0125"/>
    <!--0.328-->
    <limit effort="30" lower="-0.63" upper="0" velocity="0.5"/>
    <mimic joint="R5M_GripperJoint" multiplier="1" offset="0"/>
  </joint>
  <link name="R5M_Gripper_Left">
    <visual>
      <origin rpy="0 -1.57079632679 0" xyz="0.0 0.0 0.0"/>
      <geometry>
        <mesh filename="package://reach_system_one_support/meshes/reach5mini/visual/Base.stl"/>
      </geometry>
      <material name="Grey">
        <color rgba="0.5 0.5 0.5 1.0"/>
      </material>
    </visual>
    <collision>
      <origin rpy="0.654498469498 0 0" xyz="0 -0.02 0.035"/>
      <geometry>
        <box size="0.001 0.001 0.001"/>
      </geometry>
    </collision>
  </link>
  <link name="R5M_Gripper_Right">
    <visual>
      <origin rpy="0 -1.57079632679 0" xyz="0.0 0.0 0.0"/>
      <geometry>
        <mesh filename="package://reach_system_one_support/meshes/reach5mini/visual/Base.stl"/>
      </geometry>
      <material name="Grey">
        <color rgba="0.5 0.5 0.5 1.0"/>
      </material>
    </visual>
    <collision>
      <origin rpy="0.654498469498 0 0" xyz="0 -0.02 0.035"/>
      <geometry>
        <box size="0.001 0.001 0.001"/>
      </geometry>
    </collision>
  </link>
  <transmission name="tran15">
    <type>transmission_interface/SimpleTransmission</type>
    <joint name="R5M_GripperJoint">
      <hardwareInterface>VelocityJointInterface</hardwareInterface>
    </joint>
    <actuator name="motor15">
      <hardwareInterface>VelocityJointInterface</hardwareInterface>
      <mechanicalReduction>1</mechanicalReduction>
    </actuator>
  </transmission>
  <transmission name="tran16">
    <type>transmission_interface/SimpleTransmission</type>
    <joint name="R5M_GripperJoint2">
      <hardwareInterface>VelocityJointInterface</hardwareInterface>
    </joint>
    <actuator name="motor16">
      <hardwareInterface>VelocityJointInterface</hardwareInterface>
      <mechanicalReduction>1</mechanicalReduction>
    </actuator>
  </transmission>
</robot>

